<?xml version="1.0" ?>
<!-- =================================================================================== -->
<!-- |    This document was autogenerated by xacro from manipulator_main.xacro         | -->
<!-- |    EDITING THIS FILE BY HAND IS NOT RECOMMENDED                                 | -->
<!-- =================================================================================== -->
<robot name="archie">
  <link name="world"/>
  <!-- Fix robot to Gazebo world -->
  <joint name="fixed" type="fixed">
    <parent link="world"/>
    <child link="base_link"/>
    <origin rpy="0 0 0" xyz="0 0 0"/>
  </joint>
  <link name="base_link">
    <inertial>
      <origin rpy="0 0 0" xyz="5.34102915090199E-06 0.00149611119634719 0.027324411040906"/>
      <mass value="0.399055600639488"/>
      <inertia ixx="0.101795155" ixy="-0.0000106" ixz="-0.000004255" iyy="0.1049705" iyz="-0.0025166" izz="0.113806134"/>
    </inertial>
    <visual>
      <origin rpy="0 0 0" xyz="0 0 0"/>
      <geometry>
        <mesh filename="package://archie_description/meshes/base_link.STL"/>
      </geometry>
      <material name="">
        <color rgba="0.0549 0.4 0.3333 1.0"/>
      </material>
    </visual>
    <collision>
      <origin rpy="0 0 0" xyz="0 0 0"/>
      <geometry>
        <mesh filename="package://archie_description/meshes/base_link.STL"/>
      </geometry>
    </collision>
  </link>
  <link name="link_1">
    <inertial>
      <origin rpy="0 0 0" xyz="0.000495971250250975 -0.0119998499605218 0.0192958783777655"/>
      <mass value="0.102"/>
      <inertia ixx="0.004708" ixy="0.0000362" ixz="-0.0000863" iyy="0.0034761" iyz="-0.0013745" izz="0.0024097"/>
    </inertial>
    <visual>
      <origin rpy="0 0 0" xyz="0 0 0"/>
      <geometry>
        <mesh filename="package://archie_description/meshes/link_1.STL"/>
      </geometry>
      <material name="">
        <color rgba="0.09019 0.12549 0.164706 1.0"/>
      </material>
    </visual>
    <collision>
      <origin rpy="0 0 0" xyz="0 0 0"/>
      <geometry>
        <mesh filename="package://archie_description/meshes/link_1.STL"/>
      </geometry>
    </collision>
  </link>
  <joint name="joint_1" type="revolute">
    <origin rpy="0 0 3.14159265358979" xyz="0 0 0.07"/>
    <parent link="base_link"/>
    <child link="link_1"/>
    <axis xyz="0 0 1"/>
    <limit effort="300" lower="-1.57" upper="1.57" velocity="3"/>
  </joint>
  <link name="link_2">
    <inertial>
      <origin rpy="0 0 0" xyz="-0.00375223885247785 0.0986651693444381 3.09623365033344E-07"/>
      <mass value="0.102283747087815"/>
      <inertia ixx="0.125060728" ixy="0.017650428" ixz="0.000000038" iyy="0.0057453" iyz="-0.00000199" izz="0.1262878"/>
    </inertial>
    <visual>
      <origin rpy="0 0 0" xyz="-0.004 0.0012 0"/>
      <geometry>
        <mesh filename="package://archie_description/meshes/link_2.STL"/>
      </geometry>
      <material name="">
        <color rgba="0.1804 0.8 0.4431 1.0"/>
      </material>
    </visual>
    <collision>
      <origin rpy="0 0 0" xyz="-0.004 0.0012 0"/>
      <geometry>
        <mesh filename="package://archie_description/meshes/link_2.STL"/>
      </geometry>
    </collision>
  </link>
  <joint name="joint_2" type="revolute">
    <origin rpy="1.5707963267949 0 -1.5707963267949" xyz="0 -0.024 0.0188"/>
    <parent link="link_1"/>
    <child link="link_2"/>
    <axis xyz="0 0 1"/>
    <limit effort="300" lower="-0.78" upper="0.78" velocity="3"/>
  </joint>
  <link name="link_3">
    <inertial>
      <origin rpy="0 0 0" xyz="0.07998503185917 0.000495971402698678 0.000495878377765527"/>
      <mass value="0.102"/>
      <inertia ixx="0.004708" ixy="0.0000362" ixz="-0.0000863" iyy="0.0034761" iyz="-0.0013745" izz="0.0024097"/>
    </inertial>
    <visual>
      <origin rpy="0 0 0" xyz="0.006 0 0"/>
      <geometry>
        <mesh filename="package://archie_description/meshes/link_3.STL"/>
      </geometry>
      <material name="">
        <color rgba="0.09019 0.12549 0.164706 1.0"/>
      </material>
    </visual>
    <collision>
      <origin rpy="0 0 0" xyz="0.006 0 0"/>
      <geometry>
        <mesh filename="package://archie_description/meshes/link_3.STL"/>
      </geometry>
    </collision>
  </link>
  <joint name="joint_3" type="revolute">
    <origin rpy="0 0 1.5707963267949" xyz="-0.024 0.195 0"/>
    <parent link="link_2"/>
    <child link="link_3"/>
    <axis xyz="0 0 1"/>
    <limit effort="300" lower="-1.15" upper="2" velocity="3"/>
  </joint>
  <link name="link_4">
    <inertial>
      <origin rpy="0 0 0" xyz="-0.0140962967782675 4.33165647224752E-07 0.105115025906125"/>
      <mass value="0.105070462984836"/>
      <inertia ixx="0.1573144" ixy="0.0195671" ixz="0.0000000040" iyy="0.0051205" iyz="0.0000001350" izz="0.1589789"/>
    </inertial>
    <visual>
      <origin rpy="0 0 0" xyz="0 0 0"/>
      <geometry>
        <mesh filename="package://archie_description/meshes/link_4.STL"/>
      </geometry>
      <material name="">
        <color rgba="0.1804 0.8 0.4431 1.0"/>
      </material>
    </visual>
    <collision>
      <origin rpy="0 0 0" xyz="0 0 0"/>
      <geometry>
        <mesh filename="package://archie_description/meshes/link_4.STL"/>
      </geometry>
    </collision>
  </link>
  <joint name="joint_4" type="revolute">
    <origin rpy="1.5707963267949 0 0" xyz="0.0200000000000001 -0.02 0"/>
    <parent link="link_3"/>
    <child link="link_4"/>
    <axis xyz="0 0 1"/>
    <limit effort="200" lower="-3.14" upper="3.14" velocity="3"/>
  </joint>
  <link name="link_5">
    <inertial>
      <origin rpy="0 0 0" xyz="-0.00570412111171636 -0.00950015024510067 0.000495971250250971"/>
      <mass value="0.0982"/>
      <inertia ixx="0.004708" ixy="0.0000362" ixz="-0.0000863" iyy="0.0034761" iyz="-0.0013745" izz="0.0024097"/>
    </inertial>
    <visual>
      <origin rpy="0 0 0" xyz="0.006 -0.0025 0"/>
      <geometry>
        <mesh filename="package://archie_description/meshes/link_5.STL"/>
      </geometry>
      <material name="">
        <color rgba="0.09019 0.12549 0.164706 1.0"/>
      </material>
    </visual>
    <collision>
      <origin rpy="0 0 0" xyz="0.006 -0.0025 0"/>
      <geometry>
        <mesh filename="package://archie_description/meshes/link_5.STL"/>
      </geometry>
    </collision>
  </link>
  <joint name="joint_5" type="revolute">
    <origin rpy="-1.5707963267949 0 0" xyz="-0.02562 0 0.2075"/>
    <parent link="link_4"/>
    <child link="link_5"/>
    <axis xyz="0 0 1"/>
    <limit effort="200" lower="-1.15" upper="2" velocity="3"/>
  </joint>
  <link name="link_6">
    <inertial>
      <origin rpy="0 0 0" xyz="0.00150005999207131 2.13388833428252E-08 0.0547308096922248"/>
      <mass value="0.000147831569305485"/>
      <inertia ixx="3.66048153630127E-09" ixy="1.57772181044196E-25" ixz="1.17223439029209E-23" iyy="3.66048153630127E-09" iyz="8.32319653746676E-25" izz="7.31480342388148E-09"/>
    </inertial>
    <visual>
      <origin rpy="0 0 0" xyz="0 0 0"/>
      <geometry>
        <mesh filename="package://archie_description/meshes/link_6.STL"/>
      </geometry>
      <material name="">
        <color rgba="0.729411764705882 0.356862745098039 0.0235294117647059 1"/>
      </material>
    </visual>
    <collision>
      <origin rpy="0 0 0" xyz="0 0 0"/>
      <geometry>
        <mesh filename="package://archie_description/meshes/link_6.STL"/>
      </geometry>
    </collision>
  </link>
  <joint name="joint_6" type="revolute">
    <origin rpy="1.5707963267949 0 -1.5707963267949" xyz="-0.02 -0.024 0"/>
    <parent link="link_5"/>
    <child link="link_6"/>
    <axis xyz="0 0 1"/>
    <limit effort="200" lower="-3.14" upper="3.14" velocity="3"/>
  </joint>
  <!-- transmission list -->
  <transmission name="link_1_trans">
    <type>transmission_interface/SimpleTransmission</type>
    <joint name="joint_1">
      <hardwareInterface>hardware_interface/PositionJointInterface</hardwareInterface>
    </joint>
    <actuator name="link_1_motor">
      <hardwareInterface>hardware_interface/PositionJointInterface</hardwareInterface>
      <mechanicalReduction>1</mechanicalReduction>
    </actuator>
  </transmission>
  <transmission name="link_2_trans">
    <type>transmission_interface/SimpleTransmission</type>
    <joint name="joint_2">
      <hardwareInterface>hardware_interface/PositionJointInterface</hardwareInterface>
    </joint>
    <actuator name="link_2_motor">
      <hardwareInterface>hardware_interface/PositionJointInterface</hardwareInterface>
      <mechanicalReduction>1</mechanicalReduction>
    </actuator>
  </transmission>
  <transmission name="link_3_trans">
    <type>transmission_interface/SimpleTransmission</type>
    <joint name="joint_3">
      <hardwareInterface>hardware_interface/PositionJointInterface</hardwareInterface>
    </joint>
    <actuator name="link_3_motor">
      <hardwareInterface>hardware_interface/PositionJointInterface</hardwareInterface>
      <mechanicalReduction>1</mechanicalReduction>
    </actuator>
  </transmission>
  <transmission name="link_4_trans">
    <type>transmission_interface/SimpleTransmission</type>
    <joint name="joint_4">
      <hardwareInterface>hardware_interface/PositionJointInterface</hardwareInterface>
    </joint>
    <actuator name="link_4_motor">
      <hardwareInterface>hardware_interface/PositionJointInterface</hardwareInterface>
      <mechanicalReduction>1</mechanicalReduction>
    </actuator>
  </transmission>
  <transmission name="link_5_trans">
    <type>transmission_interface/SimpleTransmission</type>
    <joint name="joint_5">
      <hardwareInterface>hardware_interface/PositionJointInterface</hardwareInterface>
    </joint>
    <actuator name="link_5_motor">
      <hardwareInterface>hardware_interface/PositionJointInterface</hardwareInterface>
      <mechanicalReduction>1</mechanicalReduction>
    </actuator>
  </transmission>
  <transmission name="link_6_trans">
    <type>transmission_interface/SimpleTransmission</type>
    <joint name="joint_6">
      <hardwareInterface>hardware_interface/PositionJointInterface</hardwareInterface>
    </joint>
    <actuator name="link_6_motor">
      <hardwareInterface>hardware_interface/PositionJointInterface</hardwareInterface>
      <mechanicalReduction>1</mechanicalReduction>
    </actuator>
  </transmission>
  <!-- end of transmission list -->
  <!-- Gazebo-specific link properties -->
  <gazebo reference="link_1">
    <selfCollide>true</selfCollide>
    <material>Gazebo/Black</material>
  </gazebo>
  <gazebo reference="link_2">
    <selfCollide>true</selfCollide>
    <material>Gazebo/Orange</material>
  </gazebo>
  <gazebo reference="link_3">
    <selfCollide>true</selfCollide>
    <material>Gazebo/Black</material>
  </gazebo>
  <gazebo reference="link_4">
    <selfCollide>true</selfCollide>
    <material>Gazebo/Orange</material>
  </gazebo>
  <gazebo reference="link_5">
    <selfCollide>true</selfCollide>
    <material>Gazebo/Black</material>
  </gazebo>
  <gazebo reference="link_6">
    <selfCollide>true</selfCollide>
  </gazebo>
  <gazebo reference="garra1_joint">
    <selfCollide>true</selfCollide>
  </gazebo>
  <!-- ros_control plugin -->
  <gazebo>
    <plugin filename="libgazebo_ros_control.so" name="control">
      <robotNamespace>/</robotNamespace>
      <robotSimType>gazebo_ros_control/DefaultRobotHWSim</robotSimType>
    </plugin>
  </gazebo>
  <joint name="garra_joint" type="fixed">
    <parent link="link_6"/>
    <child link="base_garra"/>
    <origin rpy="0 0 1.57" xyz="0 0 0"/>
  </joint>
  <link name="base_garra">
    <inertial>
      <origin rpy="0 0 0" xyz="2.434E-05 -0.022273 -0.0046894"/>
      <mass value="0.04363"/>
      <inertia ixx="1.2763E-05" ixy="3.9172E-12" ixz="-3.6866E-11" iyy="4.6822E-05" iyz="2.0165E-06" izz="3.7148E-05"/>
    </inertial>
    <visual>
      <origin rpy="0 0 0" xyz="0 0 0"/>
      <geometry>
        <mesh filename="package://archie_description/meshes/gripper/base_garra.STL"/>
      </geometry>
      <material name="">
        <color rgba="0.6274509803921569 0.01568627450980392 0.596078431372549 1.0"/>
      </material>
    </visual>
    <collision>
      <origin rpy="0 0 0" xyz="0 0 0"/>
      <geometry>
        <mesh filename="package://archie_description/meshes/gripper/base_garra.STL"/>
      </geometry>
    </collision>
  </link>
  <link name="garra1_link">
    <inertial>
      <origin rpy="0 0 0" xyz="-0.00071849 0.018325 -0.00038068"/>
      <mass value="0.012915"/>
      <inertia ixx="4.5614E-06" ixy="-7.5789E-07" ixz="-1.3068E-07" iyy="1.565E-06" iyz="-4.7014E-07" izz="4.3774E-06"/>
    </inertial>
    <visual>
      <origin rpy="0 0 0" xyz="0 0 0"/>
      <geometry>
        <mesh filename="package://archie_description/meshes/gripper/garra1_link.STL"/>
      </geometry>
      <material name="">
        <color rgba="0.9098 0.44314 0.031373 1"/>
      </material>
    </visual>
    <collision>
      <origin rpy="0 0 0" xyz="0 0 0"/>
      <geometry>
        <mesh filename="package://archie_description/meshes/gripper/garra1_link.STL"/>
      </geometry>
    </collision>
  </link>
  <joint name="garra1_joint" type="prismatic">
    <origin rpy="0 0 0" xyz="0.043 -0.009 0.008"/>
    <parent link="base_garra"/>
    <child link="garra1_link"/>
    <axis xyz="-1 0 0"/>
    <limit effort="100" lower="0" upper="0.02" velocity="0"/>
  </joint>
  <link name="garra2_link">
    <inertial>
      <origin rpy="0 0 0" xyz="-0.00071849 0.018325 -0.00038068"/>
      <mass value="0.012915"/>
      <inertia ixx="4.5614E-06" ixy="-7.5789E-07" ixz="-1.3068E-07" iyy="1.565E-06" iyz="-4.7014E-07" izz="4.3774E-06"/>
    </inertial>
    <visual>
      <origin rpy="0 0 0" xyz="0 0 0"/>
      <geometry>
        <mesh filename="package://archie_description/meshes/gripper/garra2_link.STL"/>
      </geometry>
      <material name="">
        <color rgba="0.9098 0.44314 0.031373 1"/>
      </material>
    </visual>
    <collision>
      <origin rpy="0 0 0" xyz="0 0 0"/>
      <geometry>
        <mesh filename="package://archie_description/meshes/gripper/garra2_link.STL"/>
      </geometry>
    </collision>
  </link>
  <joint name="garra2_joint" type="prismatic">
    <origin rpy="0 0 0" xyz="-0.043 0.0125 0.008"/>
    <parent link="base_garra"/>
    <child link="garra2_link"/>
    <axis xyz="-1 0 0"/>
    <limit effort="100" lower="-0.02" upper="0" velocity="0"/>
    <mimic joint="garra1_joint" multiplier="-1" offset="0"/>
  </joint>
  <link name="end_effect_point">
    <visual>
      <origin rpy="0 0 0" xyz="0 0 0"/>
      <geometry>
        <box size="0.005 0.005 0.005"/>
      </geometry>
    </visual>
    <inertial>
      <origin rpy="0 0 0" xyz="0.0 0.0 0.0"/>
      <mass value="0.001"/>
      <inertia ixx="1.0" ixy="0.0" ixz="0.0" iyy="1.0" iyz="0.0" izz="1.0"/>
    </inertial>
  </link>
  <!--end effect point -->
  <joint name="end_effect_point" type="fixed">
    <origin rpy="3.14 0 0" xyz="0 -0.05 0.023"/>
    <parent link="base_garra"/>
    <child link="end_effect_point"/>
  </joint>
  <transmission name="garra1_trans">
    <type>transmission_interface/SimpleTransmission</type>
    <joint name="garra1_joint">
      <hardwareInterface>hardware_interface/PositionJointInterface</hardwareInterface>
    </joint>
    <actuator name="garra1_motor">
      <hardwareInterface>hardware_interface/PositionJointInterface</hardwareInterface>
      <mechanicalReduction>1</mechanicalReduction>
    </actuator>
  </transmission>
  <gazebo>
    <plugin filename="libroboticsgroup_gazebo_mimic_joint_plugin.so" name="mimic_joint_plugin">
      <joint>garra1_joint</joint>
      <mimicJoint>garra2_joint</mimicJoint>
      <multiplier>-1</multiplier>
      <offset>0</offset>
    </plugin>
  </gazebo>
</robot>

