<?xml version="1.0" ?>
<robot name="linear_gripper" xmlns:xacro="http://ros.org/wiki/xacro">

  <joint name="garra_joint" type="fixed">
    <parent link="link_6"/>
    <child link="base_garra"/>
    <origin rpy="0 0 1.57" xyz="0 0 0"/>
  </joint>

  <link
    name="base_garra">
    <inertial>
      <origin
        xyz="2.434E-05 -0.022273 -0.0046894"
        rpy="0 0 0" />
      <mass
        value="0.04363" />
      <inertia
        ixx="1.2763E-05"
        ixy="3.9172E-12"
        ixz="-3.6866E-11"
        iyy="4.6822E-05"
        iyz="2.0165E-06"
        izz="3.7148E-05"/>
    </inertial>
    <visual>
      <origin
        xyz="0 0 0"
        rpy="0 0 0" />
      <geometry>
        <mesh
          filename="package://archie_description/meshes/gripper/base_garra.STL" />
      </geometry>
      <material
        name="">
        <color rgba="0.6274509803921569 0.01568627450980392 0.596078431372549 1.0" />      
      </material>
    </visual>
    <collision>
      <origin
        xyz="0 0 0"
        rpy="0 0 0" />
      <geometry>
        <mesh
          filename="package://archie_description/meshes/gripper/base_garra.STL" />
      </geometry>
    </collision>
  </link>
  <link
    name="garra1_link">
    <inertial>
      <origin
        xyz="-0.00071849 0.018325 -0.00038068"
        rpy="0 0 0" />
      <mass
        value="0.012915" />
      <inertia
        ixx="4.5614E-06"
        ixy="-7.5789E-07"
        ixz="-1.3068E-07"
        iyy="1.565E-06"
        iyz="-4.7014E-07"
        izz="4.3774E-06" />
    </inertial>
    <visual>
      <origin
        xyz="0 0 0"
        rpy="0 0 0" />
      <geometry>
        <mesh
          filename="package://archie_description/meshes/gripper/garra1_link.STL" />
      </geometry>
      <material
        name="">
        <color
          rgba="0.9098 0.44314 0.031373 1" />
      </material>
    </visual>
    <collision>
      <origin
        xyz="0 0 0"
        rpy="0 0 0" />
      <geometry>
        <mesh
          filename="package://archie_description/meshes/gripper/garra1_link.STL" />
      </geometry>
    </collision>
  </link>
  <joint
    name="garra1_joint"
    type="prismatic">
    <origin
      xyz="0.043 -0.009 0.008"
      rpy="0 0 0" />
    <parent
      link="base_garra" />
    <child
      link="garra1_link" />
    <axis
      xyz="-1 0 0" />
    <limit
      lower="0"
      upper="0.02"
      effort="100"
      velocity="3" />
  </joint>
  <link
    name="garra2_link">
    <inertial>
      <origin
        xyz="-0.00071849 0.018325 -0.00038068"
        rpy="0 0 0" />
      <mass
        value="0.012915" />
      <inertia
        ixx="4.5614E-06"
        ixy="-7.5789E-07"
        ixz="-1.3068E-07"
        iyy="1.565E-06"
        iyz="-4.7014E-07"
        izz="4.3774E-06" />
    </inertial>
    <visual>
      <origin
        xyz="0 0 0"
        rpy="0 0 0" />
      <geometry>
        <mesh
          filename="package://archie_description/meshes/gripper/garra2_link.STL" />
      </geometry>
      <material
        name="">
        <color
          rgba="0.9098 0.44314 0.031373 1" />
      </material>
    </visual>
    <collision>
      <origin
        xyz="0 0 0"
        rpy="0 0 0" />
      <geometry>
        <mesh
          filename="package://archie_description/meshes/gripper/garra2_link.STL" />
      </geometry>
    </collision>
  </link>
  <joint
    name="garra2_joint"
    type="prismatic">
    <origin
      xyz="-0.043 0.0125 0.008"
      rpy="0 0 0" />
    <parent
      link="base_garra" />
    <child
      link="garra2_link" />
    <axis
      xyz="-1 0 0" />
    <limit
      lower="-0.02"
      upper="0"
      effort="100"
      velocity="3" />
    <mimic joint="garra1_joint" multiplier="-1" offset="0" />
  </joint>

  <link name="end_effect_point">
    <visual>
      <origin rpy="0 0 0" xyz="0 0 0"/>
      <geometry>
        <box size="0.0005 0.0005 0.0005"/>
      </geometry>
    </visual>
    <inertial>
      <origin xyz="0.0 0.0 0.0" rpy="0 0 0" />
      <mass value="0.00001" /> 
      <inertia ixx="1.0" ixy="0.0" ixz="0.0" iyy="1.0" iyz="0.0" izz="1.0" />
    </inertial>
  </link>

  <!--end effect point -->
  <joint name="end_effect_point" type="fixed">
    <origin rpy="3.14 0 0" xyz="0 -0.05 0.023"/>
    <parent link="base_garra"/>
    <child link="end_effect_point"/>
  </joint>

  <transmission name="garra1_trans">
    <type>transmission_interface/SimpleTransmission</type>
    <joint name="garra1_joint">
      <hardwareInterface>hardware_interface/PositionJointInterface</hardwareInterface>
    </joint>  
    <actuator name="garra1_motor">
      <hardwareInterface>hardware_interface/PositionJointInterface</hardwareInterface>
      <mechanicalReduction>1</mechanicalReduction>
    </actuator>
  </transmission>

  <gazebo>
    <plugin name="mimic_joint_plugin" filename="libroboticsgroup_gazebo_mimic_joint_plugin.so">
      <joint>garra1_joint</joint>
      <mimicJoint>garra2_joint</mimicJoint>
      <multiplier>-1</multiplier>
    </plugin>
  </gazebo>

</robot>