<?xml version="1.0" encoding="utf-8"?>
<!-- This URDF was automatically created by SolidWorks to URDF Exporter! Originally created by Stephen Brawner (brawner@gmail.com) 
     Commit Version: 1.6.0-4-g7f85cfe  Build Version: 1.6.7995.38578
     For more information, please see http://wiki.ros.org/sw_urdf_exporter -->
<robot
  name="manipulator">
  <!-- Fix robot to Gazebo world -->
    <link name="world" />
    <joint name="world-base_link-fixed" type="fixed">
        <parent link="world" />
        <child link="base_link" />
        <origin rpy="0.0 0.0 0.0" xyz="0.0 0.0 0.0" />
    </joint>
  
  <link
    name="base_link">
    <inertial>
      <origin
        xyz="5.34102915090199E-06 0.00149611119634719 0.027324411040906"
        rpy="0 0 0" />
      <mass
        value="0.399055600639488" />
      <inertia
        ixx="893194.67E-09"
        ixy="-102.23E-09"
        ixz="40.91E-09"
        iyy="923727.16E-09"
        iyz="24212.50E-09"
        izz="923775.69E-09" />
    </inertial>
    <visual>
      <origin
        xyz="0 0 0"
        rpy="0 0 0" />
      <geometry>
        <mesh
          filename="package://archie_description/meshes/base_link.STL" />
      </geometry>
      <material
        name="">
        <color
          rgba="0.0549 0.4 0.3333 1.0"/>
      </material>
    </visual>
    <collision>
      <origin
        xyz="0 0 0"
        rpy="0 0 0" />
      <geometry>
        <mesh
          filename="package://archie_description/meshes/base_link.STL" />
      </geometry>
    </collision>
  </link>
  <link
    name="link_1">
    <inertial>
      <origin
        xyz="0.000495971250250975 -0.0119998499605218 0.0192958783777655"
        rpy="0 0 0" />
      <mass
        value="0.102" />
      <inertia
        ixx="81136.59E-09"
        ixy="-649.99E-09"
        ixz="446.11E-09"
        iyy="59047.39E-09"
        iyz="-23574.63E-09"
        izz="43183.90E-09" />
    </inertial>
    <visual>
      <origin
        xyz="0 0 0"
        rpy="0 0 0" />
      <geometry>
        <mesh
          filename="package://archie_description/meshes/link_1.STL" />
      </geometry>
      <material
        name="">
        <color
          rgba="0.09019 0.12549 0.164706 1.0"/>
      </material>
    </visual>
    <collision>
      <origin
        xyz="0 0 0"
        rpy="0 0 0" />
      <geometry>
        <mesh
          filename="package://archie_description/meshes/link_1.STL" />
      </geometry>
    </collision>
  </link>
  <joint
    name="joint_1"
    type="revolute">
    <origin
      xyz="0 0 0.07"
      rpy="0 0 3.14159265358979" />
    <parent
      link="base_link" />
    <child
      link="link_1" />
    <axis
      xyz="0 0 1" />
    <limit
      lower="-1.57"
      upper="1.57"
      effort="300"
      velocity="3" />
  </joint>
  <link
    name="link_2">
    <inertial>
      <origin
        xyz="-0.00375223885247785 0.0986651693444381 3.09623365033344E-07"
        rpy="0 0 0" />
      <mass
        value="0.102283747087815" />
      <inertia
        ixx="1320587.76E-09"
        ixy="-135559.03E-09"
        ixz="-0.25E-09"
        iyy="48256.71E-09"
        iyz="4.14E-09"
        izz="1323662.74E-09" />
    </inertial>
    <visual>
      <origin
        xyz="-0.004 0.0012 0"
        rpy="0 0 0" />
      <geometry>
        <mesh
          filename="package://archie_description/meshes/link_2.STL" />
      </geometry>
      <material
        name="">
        <color
          rgba="0.1804 0.8 0.4431 1.0"/>
      </material>
    </visual>
    <collision>
      <origin
        xyz="-0.004 0.0012 0"
        rpy="0 0 0" />
      <geometry>
        <mesh
          filename="package://archie_description/meshes/link_2.STL" />
      </geometry>
    </collision>
  </link>
  <joint
    name="joint_2"
    type="revolute">
    <origin
      xyz="0 -0.024 0.0188"
      rpy="1.5707963267949 0 -1.5707963267949" />
    <parent
      link="link_1" />
    <child
      link="link_2" />
    <axis
      xyz="0 0 1" />
    <limit
      lower="-0.78"
      upper="0.78"
      effort="300"
      velocity="3" />
  </joint>
  <link
    name="link_3">
    <inertial>
      <origin
        xyz="0.07998503185917 0.000495971402698678 0.000495878377765527"
        rpy="0 0 0" />
      <mass
        value="0.102" />
      <inertia
        ixx="21094.66E-09"
        ixy="336.33E-09"
        ixz="250.11E-09"
        iyy="31927.33E-09"
        iyz="-504.99E-09"
        izz="31927.37E-09" />
    </inertial>
    <visual>
      <origin
        xyz="0.006 0 0"
        rpy="0 0 0" />
      <geometry>
        <mesh
          filename="package://archie_description/meshes/link_3.STL" />
      </geometry>
      <material
        name="">
        <color
          rgba="0.09019 0.12549 0.164706 1.0"/>
      </material>
    </visual>
    <collision>
      <origin
        xyz="0.006 0 0"
        rpy="0 0 0" />
      <geometry>
        <mesh
          filename="package://archie_description/meshes/link_3.STL" />
      </geometry>
    </collision>
  </link>
  <joint
    name="joint_3"
    type="revolute">
    <origin
      xyz="-0.024 0.195 0"
      rpy="0 0 1.5707963267949" />
    <parent
      link="link_2" />
    <child
      link="link_3" />
    <axis
      xyz="0 0 1" />
    <limit
      lower="-1.15"
      upper="2"
      effort="300"
      velocity="3" />
  </joint>
  <link
    name="link_4">
    <inertial>
      <origin
        xyz="-0.0140962967782675 4.33165647224752E-07 0.105115025906125"
        rpy="0 0 0" />
      <mass
        value="0.105070462984836" />
      <inertia
        ixx="1550950.52E-09"
        ixy="-0.09E-09"
        ixz="-218719.25E-09"
        iyy="1573603.83E-09"
        iyz="1.33E-09"
        izz="57213.52E-09"/>
    </inertial>
    <visual>
      <origin
        xyz="0 0 0"
        rpy="0 0 0" />
      <geometry>
        <mesh
          filename="package://archie_description/meshes/link_4.STL" />
      </geometry>
      <material
        name="">
        <color
          rgba="0.1804 0.8 0.4431 1.0"/>
      </material>
    </visual>
    <collision>
      <origin
        xyz="0 0 0"
        rpy="0 0 0" />
      <geometry>
        <mesh
          filename="package://archie_description/meshes/link_4.STL" />
      </geometry>
    </collision>
  </link>
  <joint
    name="joint_4"
    type="revolute">
    <origin
      xyz="0.0200000000000001 -0.02 0"
      rpy="1.5707963267949 0 0" />
    <parent
      link="link_3" />
    <child
      link="link_4" />
    <axis
      xyz="0 0 1" />
    <limit
      lower="-3.14"
      upper="3.14"
      effort="200"
      velocity="3" />
  </joint>
  <link
    name="link_5">
    <inertial>
      <origin
        xyz="-0.00570412111171636 -0.00950015024510067 0.000495971250250971"
        rpy="0 0 0" />
      <mass
        value="0.0982" />
      <inertia
        ixx="37702.06E-09"
        ixy="5484.11E-09"
        ixz="-818.66E-09"
        iyy="24388.33E-09"
        iyz="-437.71E-09"
        izz="40995.69E-09" />
    </inertial>
    <visual>
      <origin
        xyz="0.006 -0.0025 0"
        rpy="0 0 0" />
      <geometry>
        <mesh
          filename="package://archie_description/meshes/link_5.STL" />
      </geometry>
      <material
        name="">
        <color
          rgba="0.09019 0.12549 0.164706 1.0"/>
      </material>
    </visual>
    <collision>
      <origin
        xyz="0.006 -0.0025 0"
        rpy="0 0 0" />
      <geometry>
        <mesh
          filename="package://archie_description/meshes/link_5.STL" />
      </geometry>
    </collision>
  </link>
  <joint
    name="joint_5"
    type="revolute">
    <origin
      xyz="-0.02562 0 0.2075"
      rpy="-1.5707963267949 0 0" />
    <parent
      link="link_4" />
    <child
      link="link_5" />
    <axis
      xyz="0 0 1" />
    <limit
      lower="-1.15"
      upper="2"
      effort="200"
      velocity="3" />
  </joint>
  <link
    name="link_6">
    <inertial>
      <origin
        xyz="0.00150005999207131 2.13388833428252E-08 0.0547308096922248"
        rpy="0 0 0" />
      <mass
        value="0.01" />
      <inertia
        ixx="1533.50E-09"
        ixy="-0.01E-09"
        ixz="0.01E-09"
        iyy="1533.51E-09"
        iyz="0E-09"
        izz="360.67E-09" />
    </inertial>
    <visual>
      <origin
        xyz="0 0 0"
        rpy="0 0 0" />
      <geometry>
        <mesh
          filename="package://archie_description/meshes/link_6.STL" />
      </geometry>
      <material
        name="">
        <color
          rgba="0.729411764705882 0.356862745098039 0.0235294117647059 1" />
      </material>
    </visual>
    <collision>
      <origin
        xyz="0 0 0"
        rpy="0 0 0" />
      <geometry>
        <mesh
          filename="package://archie_description/meshes/link_6.STL" />
      </geometry>
    </collision>
  </link>
  <joint
    name="joint_6"
    type="revolute">
    <origin
      xyz="-0.02 -0.024 0"
      rpy="1.5707963267949 0 -1.5707963267949" />
    <parent
      link="link_5" />
    <child
      link="link_6" />
    <axis
      xyz="0 0 1" />
    <limit
      lower="-3.14"
      upper="3.14"
      effort="200"
      velocity="3" />
  </joint>

</robot>
