<?xml version="1.0" ?>
<!-- =================================================================================== -->
<!-- |    This document was autogenerated by xacro from /home/erick/catkin_ws/src/manipulator/manipulator_description/urdf/manipulator.xacro | -->
<!-- |    EDITING THIS FILE BY HAND IS NOT RECOMMENDED                                 | -->
<!-- =================================================================================== -->
<robot name="manipulator_robot">
    <!-- Fix robot to Gazebo world -->
    <link name="world" />
    <joint name="world-base_link-fixed" type="fixed">
        <parent link="world" />
        <child link="base_link" />
        <origin rpy="0.0 0.0 0.0" xyz="0.0 0.0 0.0" />
    </joint>
    <link name="base_link">
        <inertial>
            <origin rpy="0 0 1.57" xyz="5.34102915090225E-06 0.00149611119634718 0.027324411040906" />
            <mass value="0.391381454473344" />
            <inertia ixx="224200000" ixy="-102530000" ixz="10964000" iyy="935460000" iyz="-533770" izz="777040000" />
        </inertial>
        <visual>
            <origin rpy="0 0 1.57" xyz="0 0 0" />
            <geometry>
                <mesh filename="package://manipulator_description/meshes/base_link.STL" />
            </geometry>
            <material name="">
                <color rgba="0.698039215686274 0.698039215686274 0.698039215686274 1" />
            </material>
        </visual>
        <collision>
            <origin rpy="0 0 1.57" xyz="0 0 0" />
            <geometry>
                <mesh filename="package://manipulator_description/meshes/base_link.STL" />
            </geometry>
        </collision>
    </link>
    <link name="link_1">
        <inertial>
            <origin rpy="0 0 0" xyz="0.000495971250250978 -0.0119998499605218 0.0204959033777655" />
            <mass value="0.0569176277607128" />
            <inertia ixx="26860" ixy="525.09" ixz="287.62" iyy="16993" iyz="-523.85" izz="26995" />
        </inertial>
        <visual>
            <origin rpy="0 0 0" xyz="0 0 0" />
            <geometry>
                <mesh filename="package://manipulator_description/meshes/link_1.STL" />
            </geometry>
            <material name="">
                <color rgba="0.752941176470588 0.752941176470588 0.752941176470588 1" />
            </material>
        </visual>
        <collision>
            <origin rpy="0 0 0" xyz="0 0 0" />
            <geometry>
                <mesh filename="package://manipulator_description/meshes/link_1.STL" />
            </geometry>
        </collision>
    </link>
    <joint name="joint_1" type="revolute">
        <origin rpy="0 0 3.1416" xyz="0 0 0.0688" />
        <parent link="base_link" />
        <child link="link_1" />
        <axis xyz="0 0 1" />
        <limit effort="300" lower="-1.57" upper="1.57" velocity="3" />
    </joint>
    <link name="link_2">
        <inertial>
            <origin rpy="0 0 0" xyz="-0.0117522388524779 0.099865169344438 3.09623365025784E-07" />
            <mass value="0.102283747087815" />
            <inertia ixx="512810000" ixy="108850000" ixz="380" iyy="56237000" iyz="2370" izz="523870000" />
        </inertial>
        <visual>
            <origin rpy="0 0 0" xyz="0 0 0" />
            <geometry>
                <mesh filename="package://manipulator_description/meshes/link_2.STL" />
            </geometry>
            <material name="">
                <color rgba="0.698039215686274 0.698039215686274 0.698039215686274 1" />
            </material>
        </visual>
        <collision>
            <origin rpy="0 0 0" xyz="0 0 0" />
            <geometry>
                <mesh filename="package://manipulator_description/meshes/link_2.STL" />
            </geometry>
        </collision>
    </link>
    <joint name="joint_2" type="revolute">
        <origin rpy="1.5708 0 -1.5708" xyz="0 -0.024 0.02" />
        <parent link="link_1" />
        <child link="link_2" />
        <axis xyz="0 0 1" />
        <limit effort="300" lower="-0.78" upper="0.78" velocity="3" />
    </joint>
    <link name="link_3">
        <inertial>
            <origin rpy="0 0 0" xyz="0.000495971402698712 -0.0119998503185919 0.000495878377765541" />
            <mass value="0.0569176277607127" />
            <inertia ixx="26860" ixy="525.09" ixz="287.62" iyy="16993" iyz="-523.85" izz="26995" />
        </inertial>
        <visual>
            <origin rpy="0 0 0" xyz="0 0 0" />
            <geometry>
                <mesh filename="package://manipulator_description/meshes/link_3.STL" />
            </geometry>
            <material name="">
                <color rgba="0.752941176470588 0.752941176470588 0.752941176470588 1" />
            </material>
        </visual>
        <collision>
            <origin rpy="0 0 0" xyz="0 0 0" />
            <geometry>
                <mesh filename="package://manipulator_description/meshes/link_3.STL" />
            </geometry>
        </collision>
    </link>
    <joint name="joint_3" type="revolute">
        <origin rpy="0 0 3.1416" xyz="-0.024 0.195 0" />
        <parent link="link_2" />
        <child link="link_3" />
        <axis xyz="0 0 1" />
        <limit effort="300" lower="-1.15" upper="2" velocity="3" />
    </joint>
    <link name="link_4">
        <inertial>
            <origin rpy="0 0 0" xyz="0.0118962971363374 0.106115026058573 4.33165647320523E-07" />
            <mass value="0.105070462984835" />
            <inertia ixx="1573100000" ixy="195670000" ixz="40" iyy="51205000" iyz="1350" izz="1589800000" />
        </inertial>
        <visual>
            <origin rpy="0 0 0" xyz="0 0 0" />
            <geometry>
                <mesh filename="package://manipulator_description/meshes/link_4.STL" />
            </geometry>
            <material name="">
                <color rgba="0.698039215686274 0.698039215686274 0.698039215686274 1" />
            </material>
        </visual>
        <collision>
            <origin rpy="0 0 0" xyz="0 0 0" />
            <geometry>
                <mesh filename="package://manipulator_description/meshes/link_4.STL" />
            </geometry>
        </collision>
    </link>
    <joint name="joint_4" type="revolute">
        <origin rpy="0 0 1.5708" xyz="-0.019 -0.024 0" />
        <parent link="link_3" />
        <child link="link_4" />
        <axis xyz="0 1 0" />
        <limit effort="200" lower="-3.14" upper="3.14" velocity="3" />
    </joint>
    <link name="link_5">
        <inertial>
            <origin rpy="0 0 0" xyz="0.000495971250250887 0.0120001503975483 0.000495878530213656" />
            <mass value="0.0569176277607127" />
            <inertia ixx="26860" ixy="525.09" ixz="287.62" iyy="16993" iyz="-523.85" izz="26995" />
        </inertial>
        <visual>
            <origin rpy="0 0 0" xyz="0 0 0" />
            <geometry>
                <mesh filename="package://manipulator_description/meshes/link_5.STL" />
            </geometry>
            <material name="">
                <color rgba="0.752941176470588 0.752941176470588 0.752941176470588 1" />
            </material>
        </visual>
        <collision>
            <origin rpy="0 0 0" xyz="0 0 0" />
            <geometry>
                <mesh filename="package://manipulator_description/meshes/link_5.STL" />
            </geometry>
        </collision>
    </link>
    <joint name="joint_5" type="revolute">
        <origin rpy="0 -1.5708 0" xyz="0.024 0.2085 0" />
        <parent link="link_4" />
        <child link="link_5" />
        <axis xyz="1 0 0" />
        <limit effort="200" lower="-1.15" upper="2" velocity="3" />
    </joint>
    <link name="link_6">
        <inertial>
            <origin rpy="0 0 0" xyz="1.27935106952748E-10 -1.49986290117875E-05 0.0091913137007949" />
            <mass value="0.00405886351711359" />
            <inertia ixx="3316900" ixy="-10" ixz="0" iyy="3315500" iyz="0" izz="185540" />
        </inertial>
        <visual>
            <origin rpy="0 0 0" xyz="0 0 0" />
            <geometry>
                <mesh filename="package://manipulator_description/meshes/link_6.STL" />
            </geometry>
            <material name="">
                <color rgba="1 0.549019607843137 0 1" />
            </material>
        </visual>
        <collision>
            <origin rpy="0 0 0" xyz="0 0 0" />
            <geometry>
                <mesh filename="package://manipulator_description/meshes/link_6.STL" />
            </geometry>
        </collision>
    </link>
    <joint name="joint_6" type="revolute">
        <origin rpy="3.1416 0 -1.5354" xyz="0 0.024 -0.019" />
        <parent link="link_5" />
        <child link="link_6" />
        <axis xyz="0 0 1" />
        <limit effort="200" lower="-3.14" upper="3.14" velocity="3" />
    </joint>
    <!-- transmission list -->
    <transmission name="link_1_trans">
        <type>transmission_interface/SimpleTransmission</type>
        <joint name="joint_1">
            <hardwareInterface>hardware_interface/PositionJointInterface</hardwareInterface>
        </joint>
        <actuator name="link_1_motor">
            <hardwareInterface>hardware_interface/PositionJointInterface</hardwareInterface>
            <mechanicalReduction>1</mechanicalReduction>
        </actuator>
    </transmission>
    <transmission name="link_2_trans">
        <type>transmission_interface/SimpleTransmission</type>
        <joint name="joint_2">
            <hardwareInterface>hardware_interface/PositionJointInterface</hardwareInterface>
        </joint>
        <actuator name="link_2_motor">
            <hardwareInterface>hardware_interface/PositionJointInterface</hardwareInterface>
            <mechanicalReduction>1</mechanicalReduction>
        </actuator>
    </transmission>
    <transmission name="link_3_trans">
        <type>transmission_interface/SimpleTransmission</type>
        <joint name="joint_3">
            <hardwareInterface>hardware_interface/PositionJointInterface</hardwareInterface>
        </joint>
        <actuator name="link_3_motor">
            <hardwareInterface>hardware_interface/PositionJointInterface</hardwareInterface>
            <mechanicalReduction>1</mechanicalReduction>
        </actuator>
    </transmission>
    <transmission name="link_4_trans">
        <type>transmission_interface/SimpleTransmission</type>
        <joint name="joint_4">
            <hardwareInterface>hardware_interface/PositionJointInterface</hardwareInterface>
        </joint>
        <actuator name="link_4_motor">
            <hardwareInterface>hardware_interface/PositionJointInterface</hardwareInterface>
            <mechanicalReduction>1</mechanicalReduction>
        </actuator>
    </transmission>
    <transmission name="link_5_trans">
        <type>transmission_interface/SimpleTransmission</type>
        <joint name="joint_5">
            <hardwareInterface>hardware_interface/PositionJointInterface</hardwareInterface>
        </joint>
        <actuator name="link_5_motor">
            <hardwareInterface>hardware_interface/PositionJointInterface</hardwareInterface>
            <mechanicalReduction>1</mechanicalReduction>
        </actuator>
    </transmission>
    <transmission name="link_6_trans">
        <type>transmission_interface/SimpleTransmission</type>
        <joint name="joint_6">
            <hardwareInterface>hardware_interface/PositionJointInterface</hardwareInterface>
        </joint>
        <actuator name="link_6_motor">
            <hardwareInterface>hardware_interface/PositionJointInterface</hardwareInterface>
            <mechanicalReduction>1</mechanicalReduction>
        </actuator>
    </transmission>
    <!-- end of transmission list -->
    <!-- Gazebo-specific link properties -->
    <gazebo reference="link_1">
        <selfCollide>true</selfCollide>
        <material>Gazebo/Black</material>
        <plugin name="gazebo_ros_control">
            <robotNamespace>/</robotNamespace>
        </plugin>
    </gazebo>
    <gazebo reference="link_2">
        <selfCollide>true</selfCollide>
        <material>Gazebo/Orange</material>
    </gazebo>
    <gazebo reference="link_3">
        <selfCollide>true</selfCollide>
        <material>Gazebo/Black</material>
    </gazebo>
    <gazebo reference="link_4">
        <selfCollide>true</selfCollide>
        <material>Gazebo/Orange</material>
    </gazebo>
    <gazebo reference="link_5">
        <selfCollide>true</selfCollide>
        <material>Gazebo/Black</material>
    </gazebo>
    <gazebo reference="link_6">
        <selfCollide>true</selfCollide>
    </gazebo>
    <!-- ros_control plugin -->
    <gazebo>
        <plugin filename="libgazebo_ros_control.so" name="control">
            <robotNamespace>/</robotNamespace>
            <robotSimType>gazebo_ros_control/DefaultRobotHWSim</robotSimType>
        </plugin>
    </gazebo>
</robot>

