<?xml version="1.0" encoding="utf-8"?>
<!-- This URDF was automatically created by SolidWorks to URDF Exporter! Originally created by Stephen Brawner (brawner@gmail.com) 
     Commit Version: 1.6.0-4-g7f85cfe  Build Version: 1.6.7995.38578
     For more information, please see http://wiki.ros.org/sw_urdf_exporter -->
<robot
  name="manipulator_final2">
  <link
    name="base_link">
    <inertial>
      <origin
        xyz="5.34102915090199E-06 0.00149611119634719 0.027324411040906"
        rpy="0 0 0" />
      <mass
        value="0.399055600639488" />
<<<<<<< HEAD
      <inertia
        ixx="0.000594407764139081"
        ixy="1.10644547111889E-07"
        ixz="8.9739729973559E-09"
        iyy="0.000627271304371282"
        iyz="-7.29958201544485E-06"
        izz="0.00113695220568938" />
=======
       <inertia
        ixx="0.101795155"
        ixy="-0.0000106"
        ixz="-0.000004255"
        iyy="0.1049705"
        iyz="-0.0025166"
        izz="0.113806134" />
>>>>>>> 68e0b5f5fd7ad55b00400b91f2a0e50317acf333
    </inertial>
    <visual>
      <origin
        xyz="0 0 0"
        rpy="0 0 0" />
      <geometry>
        <mesh
          filename="package://manipulator_final2/meshes/base_link.STL" />
      </geometry>
      <material
        name="">
        <color
          rgba="0.698039215686274 0.698039215686274 0.698039215686274 1" />
      </material>
    </visual>
    <collision>
      <origin
        xyz="0 0 0"
        rpy="0 0 0" />
      <geometry>
        <mesh
          filename="package://manipulator_final2/meshes/base_link.STL" />
      </geometry>
    </collision>
  </link>
  <link
    name="link_1">
    <inertial>
      <origin
        xyz="0.000495971250250975 -0.0119998499605218 0.0192958783777655"
        rpy="0 0 0" />
      <mass
        value="0.0569176277607128" />
      <inertia
<<<<<<< HEAD
        ixx="1.43924882902027E-05"
        ixy="5.82120294435648E-10"
        ixz="3.4400350775282E-07"
        iyy="1.02302735970703E-05"
        iyz="-7.69441167802789E-10"
        izz="1.43925048825667E-05" />
=======
        ixx="0.004708"
        ixy="0.0000362"
        ixz="-0.0000863"
        iyy="0.0034761"
        iyz="-0.0013745"
        izz="0.0024097" />
>>>>>>> 68e0b5f5fd7ad55b00400b91f2a0e50317acf333
    </inertial>
    <visual>
      <origin
        xyz="0 0 0"
        rpy="0 0 0" />
      <geometry>
        <mesh
          filename="package://manipulator_final2/meshes/link_1.STL" />
      </geometry>
      <material
        name="">
        <color
          rgba="0.752941176470588 0.752941176470588 0.752941176470588 1" />
      </material>
    </visual>
    <collision>
      <origin
        xyz="0 0 0"
        rpy="0 0 0" />
      <geometry>
        <mesh
          filename="package://manipulator_final2/meshes/link_1.STL" />
      </geometry>
    </collision>
  </link>
  <joint
    name="joint_1"
    type="revolute">
    <origin
      xyz="0 0 0.07"
      rpy="0 0 3.14159265358979" />
    <parent
      link="base_link" />
    <child
      link="link_1" />
    <axis
      xyz="0 0 1" />
    <limit
      lower="-1.57"
      upper="1.57"
      effort="300"
      velocity="3" />
  </joint>
  <link
    name="link_2">
    <inertial>
      <origin
        xyz="-0.00775223885247785 0.0986651693444381 3.09623365033344E-07"
        rpy="0 0 0" />
      <mass
        value="0.102283747087815" />
      <inertia
<<<<<<< HEAD
        ixx="0.000324874196102823"
        ixy="5.73246689425898E-05"
        ixz="5.45918906463503E-12"
        iyy="4.21097504903959E-05"
        iyz="-1.01732171356313E-09"
        izz="0.000321802212764245" />
=======
        ixx="0.125060728"
        ixy="0.017650428"
        ixz="0.000000038"
        iyy="0.0057453"
        iyz="-0.00000199"
        izz="0.1262878" />
>>>>>>> 68e0b5f5fd7ad55b00400b91f2a0e50317acf333
    </inertial>
    <visual>
      <origin
        xyz="0 0 0"
        rpy="0 0 0" />
      <geometry>
        <mesh
          filename="package://manipulator_final2/meshes/link_2.STL" />
      </geometry>
      <material
        name="">
        <color
          rgba="0.698039215686274 0.698039215686274 0.698039215686274 1" />
      </material>
    </visual>
    <collision>
      <origin
        xyz="0 0 0"
        rpy="0 0 0" />
      <geometry>
        <mesh
          filename="package://manipulator_final2/meshes/link_2.STL" />
      </geometry>
    </collision>
  </link>
  <joint
    name="joint_2"
    type="revolute">
    <origin
      xyz="0 -0.02 0.02"
      rpy="1.5707963267949 0 -1.5707963267949" />
    <parent
      link="link_1" />
    <child
      link="link_2" />
    <axis
      xyz="0 0 1" />
    <limit
      lower="-0.78"
      upper="0.78"
      effort="300"
      velocity="3" />
  </joint>
  <link
    name="link_3">
    <inertial>
      <origin
        xyz="0.0057998503185917 0.000495971402698678 0.000495878377765527"
        rpy="0 0 0" />
      <mass
        value="0.0569176277607128" />
      <inertia
<<<<<<< HEAD
        ixx="1.02302735970703E-05"
        ixy="-5.8212029443209E-10"
        ixz="7.69441167803565E-10"
        iyy="1.43924882902027E-05"
        iyz="3.44003507752819E-07"
        izz="1.43925048825667E-05" />
=======
        ixx="0.004708"
        ixy="0.0000362"
        ixz="-0.0000863"
        iyy="0.0034761"
        iyz="-0.0013745"
        izz="0.0024097" />
>>>>>>> 68e0b5f5fd7ad55b00400b91f2a0e50317acf333
    </inertial>
    <visual>
      <origin
        xyz="0 0 0"
        rpy="0 0 0" />
      <geometry>
        <mesh
          filename="package://manipulator_final2/meshes/link_3.STL" />
      </geometry>
      <material
        name="">
        <color
          rgba="0.752941176470588 0.752941176470588 0.752941176470588 1" />
      </material>
    </visual>
    <collision>
      <origin
        xyz="0 0 0"
        rpy="0 0 0" />
      <geometry>
        <mesh
          filename="package://manipulator_final2/meshes/link_3.STL" />
      </geometry>
    </collision>
  </link>
  <joint
    name="joint_3"
    type="revolute">
    <origin
      xyz="-0.02 0.2 0"
      rpy="0 0 1.5707963267949" />
    <parent
      link="link_2" />
    <child
      link="link_3" />
    <axis
      xyz="0 0 1" />
    <limit
      lower="-1.15"
      upper="2"
      effort="300"
      velocity="3" />
  </joint>
  <link
    name="link_4">
    <inertial>
      <origin
        xyz="-0.0140962967782675 4.33165647224752E-07 0.105115025906125"
        rpy="0 0 0" />
      <mass
        value="0.105070462984836" />
      <inertia
<<<<<<< HEAD
        ixx="0.000389981365707822"
        ixy="-2.10320734829936E-10"
        ixz="6.30292189438459E-05"
        iyy="0.000391756095860733"
        iyz="9.03524468098893E-10"
        izz="3.63349359947086E-05" />
=======
        ixx="0.1573144"
        ixy="0.0195671"
        ixz="0.0000000040"
        iyy="0.0051205"
        iyz="0.0000001350"
        izz="0.1589789"/>
>>>>>>> 68e0b5f5fd7ad55b00400b91f2a0e50317acf333
    </inertial>
    <visual>
      <origin
        xyz="0 0 0"
        rpy="0 0 0" />
      <geometry>
        <mesh
          filename="package://manipulator_final2/meshes/link_4.STL" />
      </geometry>
      <material
        name="">
        <color
          rgba="0.698039215686274 0.698039215686274 0.698039215686274 1" />
      </material>
    </visual>
    <collision>
      <origin
        xyz="0 0 0"
        rpy="0 0 0" />
      <geometry>
        <mesh
          filename="package://manipulator_final2/meshes/link_4.STL" />
      </geometry>
    </collision>
  </link>
  <joint
    name="joint_4"
    type="revolute">
    <origin
      xyz="0.0200000000000001 -0.02 0"
      rpy="1.5707963267949 0 0" />
    <parent
      link="link_3" />
    <child
      link="link_4" />
    <axis
      xyz="0 0 1" />
    <limit
      lower="-3.14"
      upper="3.14"
      effort="200"
      velocity="3" />
  </joint>
  <link
    name="link_5">
    <inertial>
      <origin
        xyz="-0.00570412111171636 -0.00950015024510067 0.000495971250250971"
        rpy="0 0 0" />
      <mass
        value="0.0569176277607128" />
      <inertia
<<<<<<< HEAD
        ixx="1.43925048825667E-05"
        ixy="7.69441167792837E-10"
        ixz="3.44003507752818E-07"
        iyy="1.02302735970703E-05"
        iyz="-5.82120294432704E-10"
        izz="1.43924882902027E-05" />
=======
        ixx="0.004708"
        ixy="0.0000362"
        ixz="-0.0000863"
        iyy="0.0034761"
        iyz="-0.0013745"
        izz="0.0024097" />
>>>>>>> 68e0b5f5fd7ad55b00400b91f2a0e50317acf333
    </inertial>
    <visual>
      <origin
        xyz="0 0 0"
        rpy="0 0 0" />
      <geometry>
        <mesh
          filename="package://manipulator_final2/meshes/link_5.STL" />
      </geometry>
      <material
        name="">
        <color
          rgba="0.752941176470588 0.752941176470588 0.752941176470588 1" />
      </material>
    </visual>
    <collision>
      <origin
        xyz="0 0 0"
        rpy="0 0 0" />
      <geometry>
        <mesh
          filename="package://manipulator_final2/meshes/link_5.STL" />
      </geometry>
    </collision>
  </link>
  <joint
    name="joint_5"
    type="revolute">
    <origin
      xyz="-0.0200000000000001 0 0.21"
      rpy="-1.5707963267949 0 0" />
    <parent
      link="link_4" />
    <child
      link="link_5" />
    <axis
      xyz="0 0 1" />
    <limit
      lower="-1.15"
      upper="2"
      effort="200"
      velocity="3" />
  </joint>
  <link
    name="link_6">
    <inertial>
      <origin
        xyz="0.00150005999207131 2.13388833428252E-08 0.0547308096922248"
        rpy="0 0 0" />
      <mass
        value="0.0340927901942582" />
      <inertia
<<<<<<< HEAD
        ixx="3.50572329271149E-05"
        ixy="-7.61605742281189E-12"
        ixz="2.2151447327463E-11"
        iyy="3.50572267074418E-05"
        iyz="1.82035089997711E-12"
        izz="1.13056449928989E-06" />
=======
        ixx="133722.55E-9"
        ixy="0.01E-9"
        ixz="0"
        iyy="133722.55E-9"
        iyz="-0.05E-9"
        izz="1130.56E-9" />
>>>>>>> 68e0b5f5fd7ad55b00400b91f2a0e50317acf333
    </inertial>
    <visual>
      <origin
        xyz="0 0 0"
        rpy="0 0 0" />
      <geometry>
        <mesh
          filename="package://manipulator_final2/meshes/link_6.STL" />
      </geometry>
      <material
        name="">
        <color
          rgba="0.729411764705882 0.356862745098039 0.0235294117647059 1" />
      </material>
    </visual>
    <collision>
      <origin
        xyz="0 0 0"
        rpy="0 0 0" />
      <geometry>
        <mesh
          filename="package://manipulator_final2/meshes/link_6.STL" />
      </geometry>
    </collision>
  </link>
  <joint
    name="joint_6"
    type="revolute">
    <origin
      xyz="-0.04 -0.02 0"
      rpy="1.5707963267949 0 -1.5707963267949" />
    <parent
      link="link_5" />
    <child
      link="link_6" />
    <axis
      xyz="0 0 1" />
    <limit
      lower="-3.14"
      upper="3.14"
      effort="200"
      velocity="3" />
  </joint>
</robot>