<?xml version="1.0" encoding="utf-8"?>
<!-- This URDF was automatically created by SolidWorks to URDF Exporter! Originally created by Stephen Brawner (brawner@gmail.com) 
     Commit Version: 1.6.0-4-g7f85cfe  Build Version: 1.6.7995.38578
     For more information, please see http://wiki.ros.org/sw_urdf_exporter -->
<robot
  name="manipulator_final2">
  <link
    name="base_link">
    <inertial>
      <origin
        xyz="5.341E-06 0.0014961 0.027324"
        rpy="0 0 0" />
      <mass
        value="0.39906" />
      <inertia
        ixx="0.00059441"
        ixy="1.1064E-07"
        ixz="8.974E-09"
        iyy="0.00062727"
        iyz="-7.2996E-06"
        izz="0.001137" />
    </inertial>
    <visual>
      <origin
        xyz="0 0 0"
        rpy="0 0 0" />
      <geometry>
        <mesh
          filename="package://manipulator_final2/meshes/base_link.STL" />
      </geometry>
      <material
        name="">
        <color
          rgba="0.69804 0.69804 0.69804 1" />
      </material>
    </visual>
    <collision>
      <origin
        xyz="0 0 0"
        rpy="0 0 0" />
      <geometry>
        <mesh
          filename="package://manipulator_final2/meshes/base_link.STL" />
      </geometry>
    </collision>
  </link>
  <link
    name="link_1">
    <inertial>
      <origin
        xyz="0.00049597 -0.012 0.020496"
        rpy="0 0 0" />
      <mass
        value="0.056918" />
      <inertia
        ixx="1.4392E-05"
        ixy="5.8212E-10"
        ixz="3.44E-07"
        iyy="1.023E-05"
        iyz="-7.6944E-10"
        izz="1.4393E-05" />
    </inertial>
    <visual>
      <origin
        xyz="0 0 0"
        rpy="0 0 0" />
      <geometry>
        <mesh
          filename="package://manipulator_final2/meshes/link_1.STL" />
      </geometry>
      <material
        name="">
        <color
          rgba="0.75294 0.75294 0.75294 1" />
      </material>
    </visual>
    <collision>
      <origin
        xyz="0 0 0"
        rpy="0 0 0" />
      <geometry>
        <mesh
          filename="package://manipulator_final2/meshes/link_1.STL" />
      </geometry>
    </collision>
  </link>
  <joint
    name="joint_1"
    type="revolute">
    <origin
      xyz="0 0 0.0688"
      rpy="0 0 3.1416" />
    <parent
      link="base_link" />
    <child
      link="link_1" />
    <axis
      xyz="0 0 1" />
    <limit
      lower="0"
      upper="3.14"
      effort="0"
      velocity="0" />
  </joint>
  <link
    name="link_2">
    <inertial>
      <origin
        xyz="-0.011752 0.099865 3.0962E-07"
        rpy="0 0 0" />
      <mass
        value="0.10228" />
      <inertia
        ixx="0.00032487"
        ixy="5.7325E-05"
        ixz="5.4592E-12"
        iyy="4.211E-05"
        iyz="-1.0173E-09"
        izz="0.0003218" />
    </inertial>
    <visual>
      <origin
        xyz="0 0 0"
        rpy="0 0 0" />
      <geometry>
        <mesh
          filename="package://manipulator_final2/meshes/link_2.STL" />
      </geometry>
      <material
        name="">
        <color
          rgba="0.69804 0.69804 0.69804 1" />
      </material>
    </visual>
    <collision>
      <origin
        xyz="0 0 0"
        rpy="0 0 0" />
      <geometry>
        <mesh
          filename="package://manipulator_final2/meshes/link_2.STL" />
      </geometry>
    </collision>
  </link>
  <joint
    name="joint_2"
    type="revolute">
    <origin
      xyz="0 -0.024 0.02"
      rpy="1.5708 0 -1.5708" />
    <parent
      link="link_1" />
    <child
      link="link_2" />
    <axis
      xyz="0 0 1" />
    <limit
      lower="0"
      upper="3.14"
      effort="0"
      velocity="0" />
  </joint>
  <link
    name="link_3">
    <inertial>
      <origin
        xyz="0.011999850318592 0.000495971402698679 0.000495878377765527"
        rpy="0 0 0" />
      <mass
        value="0.0569176277607127" />
      <inertia
        ixx="1.02302735970703E-05"
        ixy="-5.82120294432435E-10"
        ixz="7.69441167802929E-10"
        iyy="1.43924882902026E-05"
        iyz="3.44003507752818E-07"
        izz="1.43925048825667E-05" />
    </inertial>
    <visual>
      <origin
        xyz="0 0 0"
        rpy="0 0 0" />
      <geometry>
        <mesh
          filename="package://manipulator_final2/meshes/link_3.STL" />
      </geometry>
      <material
        name="">
        <color
          rgba="0.752941176470588 0.752941176470588 0.752941176470588 1" />
      </material>
    </visual>
    <collision>
      <origin
        xyz="0 0 0"
        rpy="0 0 0" />
      <geometry>
        <mesh
          filename="package://manipulator_final2/meshes/link_3.STL" />
      </geometry>
    </collision>
  </link>
  <joint
    name="joint_3"
    type="revolute">
    <origin
      xyz="-0.024 0.195 0"
      rpy="0 0 1.5708" />
    <parent
      link="link_2" />
    <child
      link="link_3" />
    <axis
      xyz="0 0 1" />
    <limit
      lower="0"
      upper="3.14"
      effort="0"
      velocity="0" />
  </joint>
  <link
    name="link_4">
    <inertial>
      <origin
        xyz="-0.0118962971363375 4.3316564719729E-07 0.106115026058573"
        rpy="0 0 0" />
      <mass
        value="0.105070462984835" />
      <inertia
        ixx="0.000389981365707822"
        ixy="-2.10320734830229E-10"
        ixz="6.30292189438459E-05"
        iyy="0.000391756095860733"
        iyz="9.03524468095928E-10"
        izz="3.63349359947086E-05" />
    </inertial>
    <visual>
      <origin
        xyz="0 0 0"
        rpy="0 0 0" />
      <geometry>
        <mesh
          filename="package://manipulator_final2/meshes/link_4.STL" />
      </geometry>
      <material
        name="">
        <color
          rgba="0.698039215686274 0.698039215686274 0.698039215686274 1" />
      </material>
    </visual>
    <collision>
      <origin
        xyz="0 0 0"
        rpy="0 0 0" />
      <geometry>
        <mesh
          filename="package://manipulator_final2/meshes/link_4.STL" />
      </geometry>
    </collision>
  </link>
  <joint
    name="joint_4"
    type="revolute">
    <origin
      xyz="0.02400000035807 -0.0189999998475523 0"
      rpy="1.5707963267949 0 0" />
    <parent
      link="link_3" />
    <child
      link="link_4" />
    <axis
      xyz="0 0 1" />
    <limit
      lower="0"
      upper="0"
      effort="3.14"
      velocity="0" />
  </joint>
  <link
    name="link_5">
    <inertial>
      <origin
        xyz="0.000495878530213711 -0.0120001503975483 0.000495971250250903"
        rpy="0 0 0" />
      <mass
        value="0.0569176277607128" />
      <inertia
        ixx="1.43925048825667E-05"
        ixy="7.69441167802789E-10"
        ixz="3.44003507752816E-07"
        iyy="1.02302735970703E-05"
        iyz="-5.82120294432997E-10"
        izz="1.43924882902026E-05" />
    </inertial>
    <visual>
      <origin
        xyz="0 0 0"
        rpy="0 0 0" />
      <geometry>
        <mesh
          filename="package://manipulator_final2/meshes/link_5.STL" />
      </geometry>
      <material
        name="">
        <color
          rgba="0.752941176470588 0.752941176470588 0.752941176470588 1" />
      </material>
    </visual>
    <collision>
      <origin
        xyz="0 0 0"
        rpy="0 0 0" />
      <geometry>
        <mesh
          filename="package://manipulator_final2/meshes/link_5.STL" />
      </geometry>
    </collision>
  </link>
  <joint
    name="joint_5"
    type="revolute">
    <origin
      xyz="-0.024 0 0.2085"
      rpy="-1.5707963267949 0 0" />
    <parent
      link="link_4" />
    <child
      link="link_5" />
    <axis
      xyz="0 0 1" />
    <limit
      lower="0"
      upper="3.14"
      effort="0"
      velocity="0" />
  </joint>
  <link
    name="link_6">
    <inertial>
      <origin
        xyz="5.97864488471878E-08 2.13388832944287E-08 0.0686884907670907"
        rpy="0 0 0" />
      <mass
        value="0.0340927901942582" />
      <inertia
        ixx="3.50572329271149E-05"
        ixy="-7.61605742288697E-12"
        ixz="2.21514473299136E-11"
        iyy="3.50572267074418E-05"
        iyz="1.82035089103093E-12"
        izz="1.13056449928989E-06" />
    </inertial>
    <visual>
      <origin
        xyz="0 0 0"
        rpy="0 0 0" />
      <geometry>
        <mesh
          filename="package://manipulator_final2/meshes/link_6.STL" />
      </geometry>
      <material
        name="">
        <color
          rgba="0.729411764705882 0.356862745098039 0.0235294117647059 1" />
      </material>
    </visual>
    <collision>
      <origin
        xyz="0 0 0"
        rpy="0 0 0" />
      <geometry>
        <mesh
          filename="package://manipulator_final2/meshes/link_6.STL" />
      </geometry>
    </collision>
  </link>
  <joint
    name="joint_6"
    type="revolute">
    <origin
      xyz="-0.018999999847552 -0.02400000035807 0"
      rpy="1.5707963267949 0 -1.5707963267949" />
    <parent
      link="link_5" />
    <child
      link="link_6" />
    <axis
      xyz="0 0 1" />
    <limit
      lower="0"
      upper="3.14"
      effort="0"
      velocity="0" />
  </joint>
</robot>